<?xml version="1.0"?>
<robot name="simple_humanoid">
  <!-- Base/Pelvis link -->
  <link name="base_link">
    <visual>
      <geometry>
        <box size="0.15 0.25 0.15"/>
      </geometry>
      <material name="light_grey">
        <color rgba="0.7 0.7 0.7 1.0"/>
      </material>
    </visual>
    <collision>
      <geometry>
        <box size="0.15 0.25 0.15"/>
      </geometry>
    </collision>
    <inertial>
      <mass value="5.0"/>
      <inertia ixx="0.1" ixy="0.0" ixz="0.0" iyy="0.1" iyz="0.0" izz="0.1"/>
    </inertial>
  </link>

  <!-- Torso -->
  <link name="torso">
    <visual>
      <geometry>
        <box size="0.3 0.4 0.2"/>
      </geometry>
      <material name="white">
        <color rgba="1.0 1.0 1.0 1.0"/>
      </material>
    </visual>
    <collision>
      <geometry>
        <box size="0.3 0.4 0.2"/>
      </geometry>
    </collision>
    <inertial>
      <mass value="10.0"/>
      <inertia ixx="0.2" ixy="0.0" ixz="0.0" iyy="0.2" iyz="0.0" izz="0.2"/>
    </inertial>
  </link>

  <!-- Head -->
  <link name="head">
    <visual>
      <geometry>
        <sphere radius="0.1"/>
      </geometry>
      <material name="skin">
        <color rgba="1.0 0.8 0.6 1.0"/>
      </material>
    </visual>
    <collision>
      <geometry>
        <sphere radius="0.1"/>
      </geometry>
    </collision>
    <inertial>
      <mass value="2.0"/>
      <inertia ixx="0.02" ixy="0.0" ixz="0.0" iyy="0.02" iyz="0.0" izz="0.02"/>
    </inertial>
  </link>

  <!-- Right Upper Arm -->
  <link name="right_upper_arm">
    <visual>
      <geometry>
        <cylinder length="0.3" radius="0.05"/>
      </geometry>
      <material name="skin">
        <color rgba="1.0 0.8 0.6 1.0"/>
      </material>
    </visual>
    <collision>
      <geometry>
        <cylinder length="0.3" radius="0.05"/>
      </geometry>
    </collision>
    <inertial>
      <mass value="1.0"/>
      <inertia ixx="0.01" ixy="0.0" ixz="0.0" iyy="0.01" iyz="0.0" izz="0.01"/>
    </inertial>
  </link>

  <!-- Right Lower Arm -->
  <link name="right_lower_arm">
    <visual>
      <geometry>
        <cylinder length="0.25" radius="0.04"/>
      </geometry>
      <material name="skin">
        <color rgba="1.0 0.8 0.6 1.0"/>
      </material>
    </visual>
    <collision>
      <geometry>
        <cylinder length="0.25" radius="0.04"/>
      </geometry>
    </collision>
    <inertial>
      <mass value="0.8"/>
      <inertia ixx="0.008" ixy="0.0" ixz="0.0" iyy="0.008" iyz="0.0" izz="0.008"/>
    </inertial>
  </link>

  <!-- Left Upper Arm -->
  <link name="left_upper_arm">
    <visual>
      <geometry>
        <cylinder length="0.3" radius="0.05"/>
      </geometry>
      <material name="skin">
        <color rgba="1.0 0.8 0.6 1.0"/>
      </material>
    </visual>
    <collision>
      <geometry>
        <cylinder length="0.3" radius="0.05"/>
      </geometry>
    </collision>
    <inertial>
      <mass value="1.0"/>
      <inertia ixx="0.01" ixy="0.0" ixz="0.0" iyy="0.01" iyz="0.0" izz="0.01"/>
    </inertial>
  </link>

  <!-- Left Lower Arm -->
  <link name="left_lower_arm">
    <visual>
      <geometry>
        <cylinder length="0.25" radius="0.04"/>
      </geometry>
      <material name="skin">
        <color rgba="1.0 0.8 0.6 1.0"/>
      </material>
    </visual>
    <collision>
      <geometry>
        <cylinder length="0.25" radius="0.04"/>
      </geometry>
    </collision>
    <inertial>
      <mass value="0.8"/>
      <inertia ixx="0.008" ixy="0.0" ixz="0.0" iyy="0.008" iyz="0.0" izz="0.008"/>
    </inertial>
  </link>

  <!-- Right Thigh -->
  <link name="right_thigh">
    <visual>
      <geometry>
        <cylinder length="0.4" radius="0.06"/>
      </geometry>
      <material name="blue">
        <color rgba="0.2 0.4 0.8 1.0"/>
      </material>
    </visual>
    <collision>
      <geometry>
        <cylinder length="0.4" radius="0.06"/>
      </geometry>
    </collision>
    <inertial>
      <mass value="2.0"/>
      <inertia ixx="0.04" ixy="0.0" ixz="0.0" iyy="0.04" iyz="0.0" izz="0.04"/>
    </inertial>
  </link>

  <!-- Right Shin -->
  <link name="right_shin">
    <visual>
      <geometry>
        <cylinder length="0.4" radius="0.05"/>
      </geometry>
      <material name="blue">
        <color rgba="0.2 0.4 0.8 1.0"/>
      </material>
    </visual>
    <collision>
      <geometry>
        <cylinder length="0.4" radius="0.05"/>
      </geometry>
    </collision>
    <inertial>
      <mass value="1.5"/>
      <inertia ixx="0.03" ixy="0.0" ixz="0.0" iyy="0.03" iyz="0.0" izz="0.03"/>
    </inertial>
  </link>

  <!-- Right Foot -->
  <link name="right_foot">
    <visual>
      <geometry>
        <box size="0.15 0.08 0.05"/>
      </geometry>
      <material name="black">
        <color rgba="0.1 0.1 0.1 1.0"/>
      </material>
    </visual>
    <collision>
      <geometry>
        <box size="0.15 0.08 0.05"/>
      </geometry>
    </collision>
    <inertial>
      <mass value="0.5"/>
      <inertia ixx="0.001" ixy="0.0" ixz="0.0" iyy="0.001" iyz="0.0" izz="0.001"/>
    </inertial>
  </link>

  <!-- Left Thigh -->
  <link name="left_thigh">
    <visual>
      <geometry>
        <cylinder length="0.4" radius="0.06"/>
      </geometry>
      <material name="blue">
        <color rgba="0.2 0.4 0.8 1.0"/>
      </material>
    </visual>
    <collision>
      <geometry>
        <cylinder length="0.4" radius="0.06"/>
      </geometry>
    </collision>
    <inertial>
      <mass value="2.0"/>
      <inertia ixx="0.04" ixy="0.0" ixz="0.0" iyy="0.04" iyz="0.0" izz="0.04"/>
    </inertial>
  </link>

  <!-- Left Shin -->
  <link name="left_shin">
    <visual>
      <geometry>
        <cylinder length="0.4" radius="0.05"/>
      </geometry>
      <material name="blue">
        <color rgba="0.2 0.4 0.8 1.0"/>
      </material>
    </visual>
    <collision>
      <geometry>
        <cylinder length="0.4" radius="0.05"/>
      </geometry>
    </collision>
    <inertial>
      <mass value="1.5"/>
      <inertia ixx="0.03" ixy="0.0" ixz="0.0" iyy="0.03" iyz="0.0" izz="0.03"/>
    </inertial>
  </link>

  <!-- Left Foot -->
  <link name="left_foot">
    <visual>
      <geometry>
        <box size="0.15 0.08 0.05"/>
      </geometry>
      <material name="black">
        <color rgba="0.1 0.1 0.1 1.0"/>
      </material>
    </visual>
    <collision>
      <geometry>
        <box size="0.15 0.08 0.05"/>
      </geometry>
    </collision>
    <inertial>
      <mass value="0.5"/>
      <inertia ixx="0.001" ixy="0.0" ixz="0.0" iyy="0.001" iyz="0.0" izz="0.001"/>
    </inertial>
  </link>

  <!-- Joints connecting the links -->
  <joint name="base_to_torso" type="fixed">
    <parent link="base_link"/>
    <child link="torso"/>
    <origin xyz="0.0 0.0 0.25"/>
  </joint>

  <joint name="torso_to_head" type="revolute">
    <parent link="torso"/>
    <child link="head"/>
    <origin xyz="0.0 0.0 0.3"/>
    <axis xyz="0 0 1"/>
    <limit lower="-0.5" upper="0.5" effort="100" velocity="1"/>
  </joint>

  <!-- Right Arm Joints -->
  <joint name="torso_to_right_upper_arm" type="revolute">
    <parent link="torso"/>
    <child link="right_upper_arm"/>
    <origin xyz="0.2 0.0 0.1" rpy="0 0 -1.57"/>
    <axis xyz="0 1 0"/>
    <limit lower="-1.57" upper="1.57" effort="100" velocity="1"/>
  </joint>

  <joint name="right_upper_arm_to_lower_arm" type="revolute">
    <parent link="right_upper_arm"/>
    <child link="right_lower_arm"/>
    <origin xyz="0.0 0.0 -0.3"/>
    <axis xyz="0 1 0"/>
    <limit lower="-1.57" upper="1.57" effort="100" velocity="1"/>
  </joint>

  <!-- Left Arm Joints -->
  <joint name="torso_to_left_upper_arm" type="revolute">
    <parent link="torso"/>
    <child link="left_upper_arm"/>
    <origin xyz="-0.2 0.0 0.1" rpy="0 0 1.57"/>
    <axis xyz="0 1 0"/>
    <limit lower="-1.57" upper="1.57" effort="100" velocity="1"/>
  </joint>

  <joint name="left_upper_arm_to_lower_arm" type="revolute">
    <parent link="left_upper_arm"/>
    <child link="left_lower_arm"/>
    <origin xyz="0.0 0.0 -0.3"/>
    <axis xyz="0 1 0"/>
    <limit lower="-1.57" upper="1.57" effort="100" velocity="1"/>
  </joint>

  <!-- Right Leg Joints -->
  <joint name="base_to_right_thigh" type="revolute">
    <parent link="base_link"/>
    <child link="right_thigh"/>
    <origin xyz="0.0 0.0 -0.075"/>
    <axis xyz="0 1 0"/>
    <limit lower="-1.57" upper="1.57" effort="100" velocity="1"/>
  </joint>

  <joint name="right_thigh_to_shin" type="revolute">
    <parent link="right_thigh"/>
    <child link="right_shin"/>
    <origin xyz="0.0 0.0 -0.4"/>
    <axis xyz="0 1 0"/>
    <limit lower="-1.57" upper="1.57" effort="100" velocity="1"/>
  </joint>

  <joint name="right_shin_to_foot" type="revolute">
    <parent link="right_shin"/>
    <child link="right_foot"/>
    <origin xyz="0.0 0.0 -0.4"/>
    <axis xyz="1 0 0"/>
    <limit lower="-0.5" upper="0.5" effort="100" velocity="1"/>
  </joint>

  <!-- Left Leg Joints -->
  <joint name="base_to_left_thigh" type="revolute">
    <parent link="base_link"/>
    <child link="left_thigh"/>
    <origin xyz="0.0 0.0 -0.075"/>
    <axis xyz="0 1 0"/>
    <limit lower="-1.57" upper="1.57" effort="100" velocity="1"/>
  </joint>

  <joint name="left_thigh_to_shin" type="revolute">
    <parent link="left_thigh"/>
    <child link="left_shin"/>
    <origin xyz="0.0 0.0 -0.4"/>
    <axis xyz="0 1 0"/>
    <limit lower="-1.57" upper="1.57" effort="100" velocity="1"/>
  </joint>

  <joint name="left_shin_to_foot" type="revolute">
    <parent link="left_shin"/>
    <child link="left_foot"/>
    <origin xyz="0.0 0.0 -0.4"/>
    <axis xyz="1 0 0"/>
    <limit lower="-0.5" upper="0.5" effort="100" velocity="1"/>
  </joint>

  <!-- Gazebo extensions -->
  <gazebo>
    <plugin name="ground_truth" filename="libgazebo_ros_p3d.so">
      <alwaysOn>true</alwaysOn>
      <updateRate>30.0</updateRate>
      <bodyName>base_link</bodyName>
      <topicName>base_pose_ground_truth</topicName>
      <gaussianNoise>0.01</gaussianNoise>
      <frameName>map</frameName>
    </plugin>
  </gazebo>
</robot>